<mujoco model="Chebychevs lambda mechanism">
  <option timestep="0.0001"/>
  <option gravity="0 0 0"/>

  <default>
    <geom type="capsule" size=".03" rgba=".4 .7 .6 1"/>
    <default class="visual_cylinder">
      <geom type="cylinder" fromto="0 .03 0 0 -.03 0" size=".03" rgba=".3 .9 .3 .4"/>
    </default>
    <site rgba=".0 .7 0 1"/>
  </default>
  
  <worldbody>
    <light pos="0 0 10"/>
    <body name="l0" pos="0 0 0">
    <joint name="j1" type="hinge" axis="0 0 1"/>
    <geom name="D" class="visual_cylinder"/>
    <geom name="DB" fromto="0 0 0 0 0 1"/>
    <body name="BA" pos="0 0 1">
        <joint name="j2" type="hinge" axis="0 1 0"/>
        <geom name="B" class="visual_cylinder"/>
        <geom name="BA" fromto="0 0 0 0 0 0.5"/>
        <body name="AO" pos="0 0 0.5">
            <joint name="j3" type="hinge" axis="0 1 0"/>
            <geom name="A" class="visual_cylinder"/>
            <geom name="AO" fromto="0 0 0 0 0 0.25"/>
            <geom name="qw" fromto="-0.1 0 0.25 0.1 0 0.25"/>
            <geom name="qw2" fromto="-0.1 0 0.25 -0.15 0 0.35"/>
            <geom name="qw3" fromto="0.1 0 0.25 0.15 0 0.35"/>
    
        </body>
    </body>
    </body>
  </worldbody>

  <actuator>
    <position name="act1" joint="j1"/>
    <position name="act2" joint="j2"/>
    <position name="act3" joint="j3"/>
  </actuator>

</mujoco>
